Workbook
Name Chave: 'Banco de Dados'!$B$2:$B$2123
Name DataCompra: OFFSET('Banco de Dados'!$E$2, 0, 0, COUNTA('Banco de Dados'!$E:$E) - 1, 1)
Name DataPedido: OFFSET('Banco de Dados'!$D$2, 0, 0, COUNTA('Banco de Dados'!$D:$D) - 1, 1)
Name DataReembolso: OFFSET('Banco de Dados'!$AK$2, 0, 0, COUNTA('Banco de Dados'!$AK:$AK) - 1, 1)
Name ELiquido: OFFSET('Banco de Dados'!$U$2, 0, 0, COUNTA('Banco de Dados'!$U:$U) - 1, 1)
Name Loja: OFFSET('Banco de Dados'!$A$2, 0, 0, COUNTA('Banco de Dados'!$A:$A) - 1, 1)
Name PedidosClientes: OFFSET('Banco de Dados'!$C$2, 0, 0, COUNTA('Banco de Dados'!$C:$C) - 1, 1)
Name PrazoEntrega: OFFSET('Banco de Dados'!$Q$2, 0, 0, COUNTA('Banco de Dados'!$Q:$Q) - 1, 1)
Name Proxy: 'Banco de Dados'!$X$2:$X$2123
Name QtdItens: OFFSET('Banco de Dados'!$H$2, 0, 0, COUNTA('Banco de Dados'!$H:$H) - 1, 1)
Name Sku: OFFSET('Banco de Dados'!$P$2, 0, 0, COUNTA('Banco de Dados'!$P:$P) - 1, 1)
Name SMS: 'Banco de Dados'!$W$2:$W$2123
Name TaxaE: OFFSET('Banco de Dados'!$T$2, 0, 0, COUNTA('Banco de Dados'!$T:$T) - 1, 1)
Name ValorBruto: OFFSET('Banco de Dados'!$S$2, 0, 0, COUNTA('Banco de Dados'!$S:$S) - 1, 1)
Name ValorLiquido: OFFSET('Banco de Dados'!$Z$2, 0, 0, COUNTA('Banco de Dados'!$Z:$Z) - 1, 1)
Name ValorPedido: OFFSET('Banco de Dados'!$R$2, 0, 0, COUNTA('Banco de Dados'!$R:$R) - 1, 1)

Sheet OBS
A1: Sobre a planilha.
A2: Essa planilha foi estruturada para automatizar cálculos e análises a partir de entradas controladas pelo usuário, garantindo mais segurança e evitando que fórmulas sejam alteradas ou quebradas.
A4: Motor da planilha (Banco de Dados).
A5: A aba Banco de Dados é o motor do sistema.
A6: Ela concentra toda a lógica, cálculos e tratamento dos dados.
A8: Os dados inseridos pelo usuário são processados nessa aba, que por sua vez alimenta automaticamente todas as outras áreas da planilha.
A10: 👉 Ou seja:
A11: O usuário não trabalha diretamente no motor, apenas fornece os inputs.
A13: Separação entre input e cálculo.
A14: A planilha foi pensada com separação clara entre:
A16: Entradas (input humano) → onde o usuário preenche informações
A17: Processamento (Banco de Dados) → onde tudo é calculado automaticamente
... A52: Criar um sistema confiável, automatizado e resistente a erros humanos, facilitando o controle e a tomada de decisão.

Sheet Controle Pedido
A4: Loja | B4: Número Pedido Cliente | C4: Data Pedido | D4: Data Compra | E4: Pedido Fornecedor | F4: Cód Rastreamento | G4: Nome Produto | H4: Qtd | I4: CPF | J4: NOME | K4: Telefone | L4: Cep | M4: Rua | N4: Complemento | O4: SKU | P4: Prazo Entrega | Q4: Valor Pedido | R4: Valor Compra | S4: Frete
A5: BV | B5: Pedido 1 | C5: 45627 | D5: - | E5: - | F5: - | G5: Suporte de Celular Branco | H5: 1 | I5: CPF 1 | J5: Nome 1 | K5: Tel 1 | L5: Cep 1 | M5: Rua 1 | N5: Comp 1 | O5: 16-4EDB-WMZF | P5: 45639 | Q5: 14.8 | R5: 0 | S5: 0
A6: BV | B6: Pedido 2 | C6: 45627 | D6: - | E6: - | F6: - | G6: Suporte de Celular Branco | H6: 1 | I6: CPF 2 | J6: Nome 2 | K6: Tel 2 | L6: Cep 2 | M6: Rua 2 | N6: Comp 2 | O6: 16-4EDB-WMZF | P6: 45638 | Q6: 14.8 | R6: 0 | S6: 0
A7: BV | B7: Pedido 3 | C7: 45627 | D7: - | E7: - | F7: - | G7: Mini Liquidificador | H7: 1 | I7: CPF 3 | J7: Nome 3 | K7: Tel 3 | L7: Cep 3 | M7: Rua 3 | N7: Comp 3 | O7: CK-YL6M-P5Y6 | P7: 45622 | Q7: 30.99 | R7: 0 | S7: 0
A8: BV | B8: Pedido 4 | C8: 45627 | D8: - | E8: - | F8: - | G8: Bomba d'agua | H8: 1 | I8: CPF 4 | J8: Nome 4 | K8: Tel 4 | L8: Cep 4 | M8: Rua 4 | N8: Comp 4 | O8: DJ-RO5O-43GF | P8: 45626 | Q8: 16.5 | R8: 0 | S8: 0
A9: BV | B9: Pedido 5 | C9: 45627 | D9: - | E9: - | F9: - | G9: Bomba d'agua | H9: 1 | I9: CPF 5 | J9: Nome 5 | K9: Tel 5 | L9: Cep 5 | M9: Rua 5 | N9: Comp 5 | O9: DJ-RO5O-43GF | P9: 45605 | Q9: 16.99 | R9: 0 | S9: 0
A10: BV | B10: Pedido 6 | C10: 45627 | D10: - | E10: - | F10: - | G10: Mini Liquidificador | H10: 1 | I10: CPF 6 | J10: Nome 6 | K10: Tel 6 | L10: Cep 6 | M10: Rua 6 | N10: Comp 6 | O10: CK-YL6M-P5Y6 | P10: 45610 | Q10: 31.99 | R10: 0 | S10: 0
A11: BV | B11: Pedido 7 | C11: 45627 | D11: - | E11: - | F11: - | G11: Ventilador Rosa | H11: 1 | I11: CPF 7 | J11: Nome 7 | K11: Tel 7 | L11: Cep 7 | M11: Rua 7 | N11: Comp 7 | O11: IF-G2ZQ-79FO | P11: 45610 | Q11: 59.99 | R11: 0 | S11: 0
A12: BV | B12: Pedido 8 | C12: 45627 | D12: - | E12: - | F12: - | G12: Mini Liquidificador | H12: 1 | I12: CPF 8 | J12: Nome 8 | K12: Tel 8 | L12: Cep 8 | M12: Rua 8 | N12: Comp 8 | O12: CK-YL6M-P5Y6 | P12: 45602 | Q12: 26.99 | R12: 0 | S12: 0
A13: BV | B13: Pedido 9 | C13: 45627 | D13: - | E13: - | F13: - | G13: Suporte de Celular Branco | H13: 1 | I13: CPF 9 | J13: Nome 9 | K13: Tel 9 | L13: Cep 9 | M13: Rua 9 | N13: Comp 9 | O13: 16-4EDB-WMZF | P13: 45611 | Q13: 14.99 | R13: 0 | S13: 0
A14: BV | B14: Pedido 10 | C14: =Controle_Pedidos[[#This Row],[Data Compra]] -> 45585 | D14: 45585 | E14: PedidoF1 | F14: CódRastreio1 | G14: Suporte de Celular Branco | H14: 1 | I14: CPF 10 | J14: Nome 10 | K14: Tel 10 | L14: Cep 10 | M14: Rua 10 | N14: Comp 10 | O14: 16-4EDB-WMZF | P14: 45601 | Q14: 14.99 | R14: 4.99 | S14: 0
A15: BV | B15: Pedido 11 | C15: =Controle_Pedidos[[#This Row],[Data Compra]] -> 45586 | D15: 45586 | E15: PedidoF2 | F15: CódRastreio2 | G15: Suporte de Celular Preto | H15: 1 | I15: CPF 11 | J15: Nome 11 | K15: Tel 11 | L15: Cep 11 | M15: Rua 11 | N15: Comp 11 | O15: 9G-BN48-QAPH | P15: 45598 | Q15: 14.99 | R15: 4.99 | S15: 0
A16: BV | B16: Pedido 12 | C16: =Controle_Pedidos[[#This Row],[Data Compra]] -> 45586 | D16: 45586 | E16: PedidoF3 | F16: CódRastreio3 | G16: Suporte de Celular Branco | H16: 1 | I16: CPF 12 | J16: Nome 12 | K16: Tel 12 | L16: Cep 12 | M16: Rua 12 | N16: Comp 12 | O16: 16-4EDB-WMZF | P16: 45604 | Q16: 14.99 | R16: 4.99 | S16: 0
A17: BV | B17: Pedido 13 | C17: =Controle_Pedidos[[#This Row],[Data Compra]] -> 45586 | D17: 45586 | E17: PedidoF4 | F17: CódRastreio4 | G17: Suporte de Celular Preto | H17: 1 | I17: CPF 13 | J17: Nome 13 | K17: Tel 13 | L17: Cep 13 | M17: Rua 13 | N17: Comp 13 | O17: 9G-BN48-QAPH | P17: 45598 | Q17: 14.99 | R17: 4.99 | S17: 0
A18: BV | B18: Pedido 14 | C18: =Controle_Pedidos[[#This Row],[Data Compra]] -> 45586 | D18: 45586 | E18: PedidoF5 | F18: CódRastreio5 | G18: Suporte de Celular Preto | H18: 1 | I18: CPF 14 | J18: Nome 14 | K18: Tel 14 | L18: Cep 14 | M18: Rua 14 | N18: Comp 14 | O18: 9G-BN48-QAPH | P18: 45610 | Q18: 14.99 | R18: 4.99 | S18: 0
A19: BV | B19: Pedido 15 | C19: =Controle_Pedidos[[#This Row],[Data Compra]] -> 45586 | D19: 45586 | E19: PedidoF6 | F19: CódRastreio6 | G19: Bomba d'agua | H19: 1 | I19: CPF 15 | J19: Nome 15 | K19: Tel 15 | L19: Cep 15 | M19: Rua 15 | N19: Comp 15 | O19: DJ-RO5O-43GF | P19: 45610 | Q19: 17.33 | R19: 6.46 | S19: 0
A20: BV | B20: Pedido 16 | C20: =Controle_Pedidos[[#This Row],[Data Compra]] -> 45586 | D20: 45586 | E20: PedidoF7 | F20: CódRastreio7 | G20: Bomba d'agua | H20: 1 | I20: CPF 16 | J20: Nome 16 | K20: Tel 16 | L20: Cep 16 | M20: Rua 16 | N20: Comp 16 | O20: DJ-RO5O-43GF | P20: 45610 | Q20: 17.33 | R20: 6.46 | S20: 0
A21: BV | B21: Pedido 17 | C21: =Controle_Pedidos[[#This Row],[Data Compra]] -> 45586 | D21: 45586 | E21: PedidoF8 | F21: CódRastreio8 | G21: Bomba d'agua | H21: 1 | I21: CPF 17 | J21: Nome 17 | K21: Tel 17 | L21: Cep 17 | M21: Rua 17 | N21: Comp 17 | O21: DJ-RO5O-43GF | P21: 45604 | Q21: 17.33 | R21: 6.46 | S21: 0
A22: BV | B22: Pedido 18 | C22: =Controle_Pedidos[[#This Row],[Data Compra]] -> 45586 | D22: 45586 | E22: PedidoF9 | F22: CódRastreio9 | G22: Suporte de Celular Branco | H22: 1 | I22: CPF 18 | J22: Nome 18 | K22: Tel 18 | L22: Cep 18 | M22: Rua 18 | N22: Comp 18 | O22: 16-4EDB-WMZF | P22: 45610 | Q22: 14.99 | R22: 4.99 | S22: 0
A23: BV | B23: Pedido 19 | C23: =Controle_Pedidos[[#This Row],[Data Compra]] -> 45587 | D23: 45587 | E23: PedidoF10 | F23: CódRastreio10 | G23: Bomba d'agua | H23: 1 | I23: CPF 19 | J23: Nome 19 | K23: Tel 19 | L23: Cep 19 | M23: Rua 19 | N23: Comp 19 | O23: DJ-RO5O-43GF | P23: 45605 | Q23: 17.33 | R23: 6.46 | S23: 0
A24: BV | B24: Pedido 20 | C24: =Controle_Pedidos[[#This Row],[Data Compra]] -> 45587 | D24: 45587 | E24: PedidoF11 | F24: CódRastreio11 | G24: Balança | H24: 1 | I24: CPF 20 | J24: Nome 20 | K24: Tel 20 | L24: Cep 20 | M24: Rua 20 | N24: Comp 20 | O24: P4-K63S-8KOM | P24: 45605 | Q24: 17.99 | R24: 7.99 | S24: 0
A25: BV | B25: Pedido 21 | C25: =Controle_Pedidos[[#This Row],[Data Compra]] -> 45587 | D25: 45587 | E25: PedidoF12 | F25: CódRastreio12 | G25: Suporte de Celular Preto | H25: 1 | I25: CPF 21 | J25: Nome 21 | K25: Tel 21 | L25: Cep 21 | M25: Rua 21 | N25: Comp 21 | O25: 9G-BN48-QAPH | P25: 45605 | Q25: 14.99 | R25: 4.99 | S25: 0
... A365: BV | B365: Pedido 358 | C365: =Controle_Pedidos[[#This Row],[Data Compra]] -> 45608 | D365: 45608 | E365: PedidoF351 | F365: CódRastreio351 | G365: Suporte de Celular Branco | H365: 1 | I365: CPF 351 | J365: Nome 351 | K365: Tel 351 | L365: Cep 351 | M365: Rua 351 | N365: Comp 351 | O365: 16-4EDB-WMZF | P365: 45625 | Q365: 15.5 | R365: 4.99 | S365: 0
A366: BV | B366: Pedido 359 | C366: 45627 | D366: - | E366: - | F366: - | G366: Copo Termico | H366: 1 | I366: CPF 339 | J366: Nome 339 | K366: Tel 339 | L366: Cep 339 | M366: Rua 339 | N366: Comp 339 | O366: KN-TBQL-K2MM | P366: 45638 | Q366: 17.4 | R366: 0 | S366: 0
A367: BV | B367: Pedido 360 | C367: 45627 | D367: - | E367: - | F367: - | G367: Copo Termico | H367: 1 | I367: CPF 339 | J367: Nome 339 | K367: Tel 339 | L367: Cep 339 | M367: Rua 339 | N367: Comp 339 | O367: KN-TBQL-K2MM | P367: 45638 | Q367: 17.4 | R367: 0 | S367: 0
A368: BV | B368: Pedido 361 | C368: 45627 | D368: - | E368: - | F368: - | G368: Copo Termico | H368: 1 | I368: CPF 339 | J368: Nome 339 | K368: Tel 339 | L368: Cep 339 | M368: Rua 339 | N368: Comp 339 | O368: KN-TBQL-K2MM | P368: 45638 | Q368: 17.4 | R368: 0 | S368: 0
A369: BV | B369: Pedido 362 | C369: 45627 | D369: - | E369: - | F369: - | G369: Copo Termico | H369: 1 | I369: CPF 339 | J369: Nome 339 | K369: Tel 339 | L369: Cep 339 | M369: Rua 339 | N369: Comp 339 | O369: KN-TBQL-K2MM | P369: 45638 | Q369: 17.4 | R369: 0 | S369: 0
A370: BV | B370: Pedido 363 | C370: =Controle_Pedidos[[#This Row],[Data Compra]] -> 45610 | D370: 45610 | E370: PedidoF352 | F370: CódRastreio352 | G370: Ventilador Preto | H370: 1 | I370: CPF 352 | J370: Nome 352 | K370: Tel 352 | L370: Cep 352 | M370: Rua 352 | N370: Comp 352 | O370: MU-J80P-95WF | P370: 45645 | Q370: 59.5 | R370: 0 | S370: 0
A371: BV | B371: Pedido 363 | C371: =Controle_Pedidos[[#This Row],[Data Compra]] -> 45609 | D371: 45609 | E371: PedidoF353 | F371: CódRastreio353 | G371: Ventilador Rosa | H371: 1 | I371: CPF 352 | J371: Nome 352 | K371: Tel 352 | L371: Cep 352 | M371: Rua 352 | N371: Comp 352 | O371: IF-G2ZQ-79FO | P371: 45645 | Q371: 59.5 | R371: 0 | S371: 0
A372: BV | B372: Pedido 364 | C372: =Controle_Pedidos[[#This Row],[Data Compra]] -> 45609 | D372: 45609 | E372: PedidoF354 | F372: CódRastreio354 | G372: Suporte de Celular Preto | H372: 1 | I372: CPF 353 | J372: Nome 353 | K372: Tel 353 | L372: Cep 353 | M372: Rua 353 | N372: Comp 353 | O372: 9G-BN48-QAPH | P372: 45638 | Q372: 17.99 | R372: 0 | S372: 0
A373: BV | B373: Pedido 365 | C373: =Controle_Pedidos[[#This Row],[Data Compra]] -> 45609 | D373: 45609 | E373: PedidoF355 | F373: CódRastreio355 | G373: Mini Liquidificador | H373: 1 | I373: CPF 354 | J373: Nome 354 | K373: Tel 354 | L373: Cep 354 | M373: Rua 354 | N373: Comp 354 | O373: CK-YL6M-P5Y6 | P373: 45638 | Q373: 31.5 | R373: 11.99 | S373: 0
A374: BV | B374: Pedido 366 | C374: =Controle_Pedidos[[#This Row],[Data Compra]] -> 45609 | D374: 45609 | E374: PedidoF356 | F374: CódRastreio356 | G374: Suporte de Celular Preto | H374: 1 | I374: CPF 355 | J374: Nome 355 | K374: Tel 355 | L374: Cep 355 | M374: Rua 355 | N374: Comp 355 | O374: 9G-BN48-QAPH | P374: 45632 | Q374: 17.99 | R374: 6.99 | S374: 0
A375: BV | B375: Pedido 367 | C375: =Controle_Pedidos[[#This Row],[Data Compra]] -> 45609 | D375: 45609 | E375: PedidoF357 | F375: CódRastreio357 | G375: Ventilador de teto | H375: 1 | I375: CPF 356 | J375: Nome 356 | K375: Tel 356 | L375: Cep 356 | M375: Rua 356 | N375: Comp 356 | O375: BP-NHG2-B8C1 | P375: 45638 | Q375: 49.5 | R375: 10.71 | S375: 0
A376: BV | B376: Pedido 368 | C376: =Controle_Pedidos[[#This Row],[Data Compra]] -> 45609 | D376: 45609 | E376: PedidoF358 | F376: CódRastreio358 | G376: Copo Termico | H376: 1 | I376: CPF 357 | J376: Nome 357 | K376: Tel 357 | L376: Cep 357 | M376: Rua 357 | N376: Comp 357 | O376: KN-TBQL-K2MM | P376: 45638 | Q376: 17.4 | R376: 6.99 | S376: 0
A377: BV | B377: Pedido 369 | C377: =Controle_Pedidos[[#This Row],[Data Compra]] -> 45609 | D377: 45609 | E377: PedidoF359 | F377: CódRastreio359 | G377: Mini Liquidificador | H377: 1 | I377: CPF 358 | J377: Nome 358 | K377: Tel 358 | L377: Cep 358 | M377: Rua 358 | N377: Comp 358 | O377: CK-YL6M-P5Y6 | P377: 45638 | Q377: 31.5 | R377: 11.99 | S377: 0
A378: BV | B378: Pedido 370 | C378: =Controle_Pedidos[[#This Row],[Data Compra]] -> 45609 | D378: 45609 | E378: PedidoF360 | F378: CódRastreio360 | G378: Ventilador Azul | H378: 1 | I378: CPF 359 | J378: Nome 359 | K378: Tel 359 | L378: Cep 359 | M378: Rua 359 | N378: Comp 359 | O378: U8-2VWS-OB6M | P378: 45638 | Q378: 59.5 | R378: 10.18 | S378: 0
A379: BV | B379: Pedido 371 | C379: =Controle_Pedidos[[#This Row],[Data Compra]] -> 45610 | D379: 45610 | E379: PedidoF361 | F379: CódRastreio361 | G379: Suporte de Celular Preto | H379: 1 | I379: CPF 360 | J379: Nome 360 | K379: Tel 360 | L379: Cep 360 | M379: Rua 360 | N379: Comp 360 | O379: 9G-BN48-QAPH | P379: 45639 | Q379: 18.5 | R379: 6.99 | S379: 0
A380: BV | B380: Pedido 372 | C380: =Controle_Pedidos[[#This Row],[Data Compra]] -> 45610 | D380: 45610 | E380: PedidoF362 | F380: CódRastreio362 | G380: Ventilador Preto | H380: 1 | I380: CPF 361 | J380: Nome 361 | K380: Tel 361 | L380: Cep 361 | M380: Rua 361 | N380: Comp 361 | O380: MU-J80P-95WF | P380: 45639 | Q380: 59.5 | R380: 10.23 | S380: 0
A381: BV | B381: Pedido 373 | C381: =Controle_Pedidos[[#This Row],[Data Compra]] -> 45610 | D381: 45610 | E381: PedidoF363 | F381: CódRastreio363 | G381: Mini Liquidificador | H381: 1 | I381: CPF 362 | J381: Nome 362 | K381: Tel 362 | L381: Cep 362 | M381: Rua 362 | N381: Comp 362 | O381: CK-YL6M-P5Y6 | P381: 45633 | Q381: 29.5 | R381: 11.99 | S381: 0
... A412: BV | B412: Pedido 404 | C412: =Controle_Pedidos[[#This Row],[Data Compra]] -> 45616 | D412: 45616 | E412: PedidoF394 | F412: CódRastreio394 | G412: Ventilador Umidificador Branco | H412: 1 | I412: CPF 391 | J412: Nome 391 | K412: Tel 391 | L412: Cep 391 | M412: Rua 391 | N412: Comp 391 | O412: IA-LLX9-MRV1 | P412: 45643 | Q412: 52.99 | R412: 10.18 | S412: 0
...

Sheet Follow Up
A2: Contagem de Id Pedido | B2: Rótulos de Coluna | F2: Rótulos de Linha | G2: Contagem de CODRASTREIO
A3: Rótulos de Linha | B3: Brasil | C3: China | D3: Total Geral | F3: Dentro do Prazo | G3: 1801 | H3: =G3/$G$5 -> 0.91097623
A4: EM SEPARAÇÃO | B4: 3 | C4: 11 | D4: 14 | F4: Fora do Prazo | G4: 176 | H4: =G4/$G$5 -> 0.089023773
A5: RETORNANDO | C5: 2 | D5: 2 | F5: Total Geral | G5: 1977
A6: EM TRÂNSITO | B6: 9 | C6: 2 | D6: 11
A7: Total Geral | B7: 12 | C7: 15 | D7: 27
A11: Id Pedido | B11: CODRASTREIO | C11: CODRASTREIO2 | D11: Loja | E11: Prev Entrega | F11: Transp | G11: Novo Cód de Rastreio | H11: PAISORIGEM | I11: PAISDESTINO | J11: DATAATUALIZAÇÃO | K11: - | L11: STATUS | M11: Obs | N11: Prazo | O11: MSG
A12: Pedido 363 | B12: CódRastreio352 1 envio | C12: =Follow[[#This Row],[CODRASTREIO]]&" B" -> CódRastreio352 1 envio B | D12: BV | E12: 45645 | F12: Transp 1 | G12: - | H12: China | I12: Brasil | J12: 45644 | K12: Entregue | L12: ENTREGUE | M12: Fornecedor não vai Reembolsar | N12: =IF(Follow[[#This Row],[DATAATUALIZAÇÃO]]<=Follow[[#This Row],[Prev Entrega]],"Dentro do Prazo","Fora do Prazo") -> Dentro do Prazo | O12: =_xlfn.CONCAT("Olá ",PROPER(LOWER(TRIM(LEFT(SUBSTITUTE(_xlfn.XLOOKUP(Follow[[#This Row],[Id Pedido]],Controle_Pedidos[Número Pedido Cliente],Controle_Pedidos[NOME])," ",REPT(" ",100)),100)))),", Identificamos que o Item ",_xlfn.XLOOKUP(Follow[[#This Row],[Id Pedido]],Controle_Pedidos[Número Pedido Cliente],Controle_Pedidos[Nome Produto])," foi entregue no dia ",TEXT(Follow[[#This Row],[DATAATUALIZAÇÃO]],"dd/mm/aaaa"),", referente ao pedido Nº ",Follow[[#This Row],[Id Pedido]]," Rastreio ",IF(Follow[[#This Row],[Novo Cód de Rastreio]]="-",Follow[[#This Row],[Id Pedido]],Follow[[#This Row],[Novo Cód de Rastreio]]),", agradecemos a preferência e adoraríamos receber sua avaliação, tendo qualquer dúvida estamos à disposição.",_xlfn.IFS(Follow[[#This Row],[Loja]]="bv"," Att Tem tudo Shop",Follow[[#This Row],[Loja]]="mei"," Att NTA Variedades",Follow[[#This Row],[Loja]]="go"," Att Sec Variedades")) -> Olá Nome, Identificamos que o Item Ventilador Preto foi entregue no dia 18/12/2024, referente ao pedido Nº Pedido 363 Rastreio Pedido 363, agradecemos a preferência e adoraríamos receber sua avaliação, tendo qualquer dúvida estamos à disposição. Att Tem tudo Shop
A13: =_xlfn.XLOOKUP(Follow[[#This Row],[CODRASTREIO]],Controle_Pedidos[Cód Rastreamento],Controle_Pedidos[Número Pedido Cliente]) -> Pedido 363 | B13: CódRastreio352 | C13: =Follow[[#This Row],[CODRASTREIO]]&" B" -> CódRastreio352 B | D13: =_xlfn.XLOOKUP(Follow[[#This Row],[Id Pedido]],Controle_Pedidos[Número Pedido Cliente],Controle_Pedidos[Loja]) -> BV | E13: =_xlfn.XLOOKUP(Follow[[#This Row],[Id Pedido]],Controle_Pedidos[Número Pedido Cliente],Controle_Pedidos[Prazo Entrega]) -> 45645 | F13: Transp 1 | G13: - | H13: China | I13: Brasil | J13: 45644 | K13: Entregue | L13: ENTREGUE | M13: Cliente Notificado | N13: =IF(Follow[[#This Row],[DATAATUALIZAÇÃO]]<=Follow[[#This Row],[Prev Entrega]],"Dentro do Prazo","Fora do Prazo") -> Dentro do Prazo | O13: =_xlfn.CONCAT("Olá ",PROPER(LOWER(TRIM(LEFT(SUBSTITUTE(_xlfn.XLOOKUP(Follow[[#This Row],[Id Pedido]],Controle_Pedidos[Número Pedido Cliente],Controle_Pedidos[NOME])," ",REPT(" ",100)),100)))),", Identificamos que o Item ",_xlfn.XLOOKUP(Follow[[#This Row],[Id Pedido]],Controle_Pedidos[Número Pedido Cliente],Controle_Pedidos[Nome Produto])," foi entregue no dia ",TEXT(Follow[[#This Row],[DATAATUALIZAÇÃO]],"dd/mm/aaaa"),", referente ao pedido Nº ",Follow[[#This Row],[Id Pedido]]," Rastreio ",IF(Follow[[#This Row],[Novo Cód de Rastreio]]="-",Follow[[#This Row],[Id Pedido]],Follow[[#This Row],[Novo Cód de Rastreio]]),", agradecemos a preferência e adoraríamos receber sua avaliação, tendo qualquer dúvida estamos à disposição.",_xlfn.IFS(Follow[[#This Row],[Loja]]="bv"," Att Tem tudo Shop",Follow[[#This Row],[Loja]]="mei"," Att NTA Variedades",Follow[[#This Row],[Loja]]="go"," Att Sec Variedades")) -> Olá Nome, Identificamos que o Item Ventilador Preto foi entregue no dia 18/12/2024, referente ao pedido Nº Pedido 363 Rastreio Pedido 363, agradecemos a preferência e adoraríamos receber sua avaliação, tendo qualquer dúvida estamos à disposição. Att Tem tudo Shop
A14: =_xlfn.XLOOKUP(Follow[[#This Row],[CODRASTREIO]],Controle_Pedidos[Cód Rastreamento],Controle_Pedidos[Número Pedido Cliente]) -> Pedido 543 | B14: CódRastreio528 | C14: =Follow[[#This Row],[CODRASTREIO]]&" B" -> CódRastreio528 B | D14: =_xlfn.XLOOKUP(Follow[[#This Row],[Id Pedido]],Controle_Pedidos[Número Pedido Cliente],Controle_Pedidos[Loja]) -> BV | E14: =_xlfn.XLOOKUP(Follow[[#This Row],[Id Pedido]],Controle_Pedidos[Número Pedido Cliente],Controle_Pedidos[Prazo Entrega]) -> 45665 | F14: Transp 1 | G14: - | H14: Brasil | I14: Brasil | J14: 45679 | K14: Entregue | L14: ENTREGUE | M14: - | N14: =IF(Follow[[#This Row],[DATAATUALIZAÇÃO]]<=Follow[[#This Row],[Prev Entrega]],"Dentro do Prazo","Fora do Prazo") -> Fora do Prazo | O14: =_xlfn.CONCAT("Olá ",PROPER(LOWER(TRIM(LEFT(SUBSTITUTE(_xlfn.XLOOKUP(Follow[[#This Row],[Id Pedido]],Controle_Pedidos[Número Pedido Cliente],Controle_Pedidos[NOME])," ",REPT(" ",100)),100)))),", Identificamos que o Item ",_xlfn.XLOOKUP(Follow[[#This Row],[Id Pedido]],Controle_Pedidos[Número Pedido Cliente],Controle_Pedidos[Nome Produto])," foi entregue no dia ",TEXT(Follow[[#This Row],[DATAATUALIZAÇÃO]],"dd/mm/aaaa"),", referente ao pedido Nº ",Follow[[#This Row],[Id Pedido]]," Rastreio ",IF(Follow[[#This Row],[Novo Cód de Rastreio]]="-",Follow[[#This Row],[Id Pedido]],Follow[[#This Row],[Novo Cód de Rastreio]]),", agradecemos a preferência e adoraríamos receber sua avaliação, tendo qualquer dúvida estamos à disposição.",_xlfn.IFS(Follow[[#This Row],[Loja]]="bv"," Att Tem tudo Shop",Follow[[#This Row],[Loja]]="mei"," Att NTA Variedades",Follow[[#This Row],[Loja]]="go"," Att Sec Variedades")) -> Olá Nome, Identificamos que o Item Suporte de Celular Branco foi entregue no dia 22/01/2025, referente ao pedido Nº Pedido 543 Rastreio Pedido 543, agradecemos a preferência e adoraríamos receber sua avaliação, tendo qualquer dúvida estamos à disposição. Att Tem tudo Shop
A15: =_xlfn.XLOOKUP(Follow[[#This Row],[CODRASTREIO]],Controle_Pedidos[Cód Rastreamento],Controle_Pedidos[Número Pedido Cliente]) -> Pedido 560 | B15: CódRastreio545 | C15: =Follow[[#This Row],[CODRASTREIO]]&" B" -> CódRastreio545 B | D15: =_xlfn.XLOOKUP(Follow[[#This Row],[Id Pedido]],Controle_Pedidos[Número Pedido Cliente],Controle_Pedidos[Loja]) -> BV | E15: =_xlfn.XLOOKUP(Follow[[#This Row],[Id Pedido]],Controle_Pedidos[Número Pedido Cliente],Controle_Pedidos[Prazo Entrega]) -> 45666 | F15: Transp 1 | G15: - | H15: China | I15: Brasil | J15: 45645 | K15: Entregue | L15: ENTREGUE | M15: Aguardando reembolso | N15: =IF(Follow[[#This Row],[DATAATUALIZAÇÃO]]<=Follow[[#This Row],[Prev Entrega]],"Dentro do Prazo","Fora do Prazo") -> Dentro do Prazo | O15: =_xlfn.CONCAT("Olá ",PROPER(LOWER(TRIM(LEFT(SUBSTITUTE(_xlfn.XLOOKUP(Follow[[#This Row],[Id Pedido]],Controle_Pedidos[Número Pedido Cliente],Controle_Pedidos[NOME])," ",REPT(" ",100)),100)))),", Identificamos que o Item ",_xlfn.XLOOKUP(Follow[[#This Row],[Id Pedido]],Controle_Pedidos[Número Pedido Cliente],Controle_Pedidos[Nome Produto])," foi entregue no dia ",TEXT(Follow[[#This Row],[DATAATUALIZAÇÃO]],"dd/mm/aaaa"),", referente ao pedido Nº ",Follow[[#This Row],[Id Pedido]]," Rastreio ",IF(Follow[[#This Row],[Novo Cód de Rastreio]]="-",Follow[[#This Row],[Id Pedido]],Follow[[#This Row],[Novo Cód de Rastreio]]),", agradecemos a preferência e adoraríamos receber sua avaliação, tendo qualquer dúvida estamos à disposição.",_xlfn.IFS(Follow[[#This Row],[Loja]]="bv"," Att Tem tudo Shop",Follow[[#This Row],[Loja]]="mei"," Att NTA Variedades",Follow[[#This Row],[Loja]]="go"," Att Sec Variedades")) -> Olá Nome, Identificamos que o Item Ventilador Rosa foi entregue no dia 19/12/2024, referente ao pedido Nº Pedido 560 Rastreio Pedido 560, agradecemos a preferência e adoraríamos receber sua avaliação, tendo qualquer dúvida estamos à disposição. Att Tem tudo Shop
A16: =_xlfn.XLOOKUP(Follow[[#This Row],[CODRASTREIO]],Controle_Pedidos[Cód Rastreamento],Controle_Pedidos[Número Pedido Cliente]) -> Pedido 574 | B16: CódRastreio559 | C16: =Follow[[#This Row],[CODRASTREIO]]&" B" -> CódRastreio559 B | D16: =_xlfn.XLOOKUP(Follow[[#This Row],[Id Pedido]],Controle_Pedidos[Número Pedido Cliente],Controle_Pedidos[Loja]) -> BV | E16: =_xlfn.XLOOKUP(Follow[[#This Row],[Id Pedido]],Controle_Pedidos[Número Pedido Cliente],Controle_Pedidos[Prazo Entrega]) -> 45666 | F16: Transp 1 | G16: - | H16: China | I16: Brasil | J16: 45646 | K16: Entregue | L16: ENTREGUE | M16: - | N16: =IF(Follow[[#This Row],[DATAATUALIZAÇÃO]]<=Follow[[#This Row],[Prev Entrega]],"Dentro do Prazo","Fora do Prazo") -> Dentro do Prazo | O16: =_xlfn.CONCAT("Olá ",PROPER(LOWER(TRIM(LEFT(SUBSTITUTE(_xlfn.XLOOKUP(Follow[[#This Row],[Id Pedido]],Controle_Pedidos[Número Pedido Cliente],Controle_Pedidos[NOME])," ",REPT(" ",100)),100)))),", Identificamos que o Item ",_xlfn.XLOOKUP(Follow[[#This Row],[Id Pedido]],Controle_Pedidos[Número Pedido Cliente],Controle_Pedidos[Nome Produto])," foi entregue no dia ",TEXT(Follow[[#This Row],[DATAATUALIZAÇÃO]],"dd/mm/aaaa"),", referente ao pedido Nº ",Follow[[#This Row],[Id Pedido]]," Rastreio ",IF(Follow[[#This Row],[Novo Cód de Rastreio]]="-",Follow[[#This Row],[Id Pedido]],Follow[[#This Row],[Novo Cód de Rastreio]]),", agradecemos a preferência e adoraríamos receber sua avaliação, tendo qualquer dúvida estamos à disposição.",_xlfn.IFS(Follow[[#This Row],[Loja]]="bv"," Att Tem tudo Shop",Follow[[#This Row],[Loja]]="mei"," Att NTA Variedades",Follow[[#This Row],[Loja]]="go"," Att Sec Variedades")) -> Olá Nome, Identificamos que o Item Ventilador Preto foi entregue no dia 20/12/2024, referente ao pedido Nº Pedido 574 Rastreio Pedido 574, agradecemos a preferência e adoraríamos receber sua avaliação, tendo qualquer dúvida estamos à disposição. Att Tem tudo Shop
A17: =_xlfn.XLOOKUP(Follow[[#This Row],[CODRASTREIO]],Controle_Pedidos[Cód Rastreamento],Controle_Pedidos[Número Pedido Cliente]) -> Pedido 555 | B17: CódRastreio540 | C17: =Follow[[#This Row],[CODRASTREIO]]&" B" -> CódRastreio540 B | D17: =_xlfn.XLOOKUP(Follow[[#This Row],[Id Pedido]],Controle_Pedidos[Número Pedido Cliente],Controle_Pedidos[Loja]) -> BV | E17: =_xlfn.XLOOKUP(Follow[[#This Row],[Id Pedido]],Controle_Pedidos[Número Pedido Cliente],Controle_Pedidos[Prazo Entrega]) -> 45666 | F17: Transp 1 | G17: - | H17: China | I17: Brasil | J17: 45664 | K17: Entregue | L17: ENTREGUE | M17: Aguardando reembolso | N17: =IF(Follow[[#This Row],[DATAATUALIZAÇÃO]]<=Follow[[#This Row],[Prev Entrega]],"Dentro do Prazo","Fora do Prazo") -> Dentro do Prazo | O17: =_xlfn.CONCAT("Olá ",PROPER(LOWER(TRIM(LEFT(SUBSTITUTE(_xlfn.XLOOKUP(Follow[[#This Row],[Id Pedido]],Controle_Pedidos[Número Pedido Cliente],Controle_Pedidos[NOME])," ",REPT(" ",100)),100)))),", Identificamos que o Item ",_xlfn.XLOOKUP(Follow[[#This Row],[Id Pedido]],Controle_Pedidos[Número Pedido Cliente],Controle_Pedidos[Nome Produto])," foi entregue no dia ",TEXT(Follow[[#This Row],[DATAATUALIZAÇÃO]],"dd/mm/aaaa"),", referente ao pedido Nº ",Follow[[#This Row],[Id Pedido]]," Rastreio ",IF(Follow[[#This Row],[Novo Cód de Rastreio]]="-",Follow[[#This Row],[Id Pedido]],Follow[[#This Row],[Novo Cód de Rastreio]]),", agradecemos a preferência e adoraríamos receber sua avaliação, tendo qualquer dúvida estamos à disposição.",_xlfn.IFS(Follow[[#This Row],[Loja]]="bv"," Att Tem tudo Shop",Follow[[#This Row],[Loja]]="mei"," Att NTA Variedades",Follow[[#This Row],[Loja]]="go"," Att Sec Variedades")) -> Olá Nome, Identificamos que o Item Ventilador de teto foi entregue no dia 07/01/2025, referente ao pedido Nº Pedido 555 Rastreio Pedido 555, agradecemos a preferência e adoraríamos receber sua avaliação, tendo qualquer dúvida estamos à disposição. Att Tem tudo Shop
A18: =_xlfn.XLOOKUP(Follow[[#This Row],[CODRASTREIO]],Controle_Pedidos[Cód Rastreamento],Controle_Pedidos[Número Pedido Cliente]) -> Pedido 597 | B18: CódRastreio582 | C18: =Follow[[#This Row],[CODRASTREIO]]&" B" -> CódRastreio582 B | D18: =_xlfn.XLOOKUP(Follow[[#This Row],[Id Pedido]],Controle_Pedidos[Número Pedido Cliente],Controle_Pedidos[Loja]) -> BV | E18: =_xlfn.XLOOKUP(Follow[[#This Row],[Id Pedido]],Controle_Pedidos[Número Pedido Cliente],Controle_Pedidos[Prazo Entrega]) -> 45686 | F18: Transp 1 | G18: - | H18: China | I18: Brasil | J18: 45692 | K18: Entregue | L18: ENTREGUE | M18: - | N18: =IF(Follow[[#This Row],[DATAATUALIZAÇÃO]]<=Follow[[#This Row],[Prev Entrega]],"Dentro do Prazo","Fora do Prazo") -> Fora do Prazo | O18: =_xlfn.CONCAT("Olá ",PROPER(LOWER(TRIM(LEFT(SUBSTITUTE(_xlfn.XLOOKUP(Follow[[#This Row],[Id Pedido]],Controle_Pedidos[Número Pedido Cliente],Controle_Pedidos[NOME])," ",REPT(" ",100)),100)))),", Identificamos que o Item ",_xlfn.XLOOKUP(Follow[[#This Row],[Id Pedido]],Controle_Pedidos[Número Pedido Cliente],Controle_Pedidos[Nome Produto])," foi entregue no dia ",TEXT(Follow[[#This Row],[DATAATUALIZAÇÃO]],"dd/mm/aaaa"),", referente ao pedido Nº ",Follow[[#This Row],[Id Pedido]]," Rastreio ",IF(Follow[[#This Row],[Novo Cód de Rastreio]]="-",Follow[[#This Row],[Id Pedido]],Follow[[#This Row],[Novo Cód de Rastreio]]),", agradecemos a preferência e adoraríamos receber sua avaliação, tendo qualquer dúvida estamos à disposição.",_xlfn.IFS(Follow[[#This Row],[Loja]]="bv"," Att Tem tudo Shop",Follow[[#This Row],[Loja]]="mei"," Att NTA Variedades",Follow[[#This Row],[Loja]]="go"," Att Sec Variedades")) -> Olá Nome, Identificamos que o Item Ventilador Preto foi entregue no dia 04/02/2025, referente ao pedido Nº Pedido 597 Rastreio Pedido 597, agradecemos a preferência e adoraríamos receber sua avaliação, tendo qualquer dúvida estamos à disposição. Att Tem tudo Shop | R18: Olá Nome, Identificamos que o Item Ventilador Preto foi entregue no dia 18/12/2024, referente ao pedido Nº Pedido 363 Rastreio CódRastreio352, agradecemos a preferência e adoraríamos receber sua avaliação, tendo qualquer dúvida estamos à disposição. Att Tem tudo Shop
A19: =_xlfn.XLOOKUP(Follow[[#This Row],[CODRASTREIO]],Controle_Pedidos[Cód Rastreamento],Controle_Pedidos[Número Pedido Cliente]) -> Pedido 611 | B19: CódRastreio594 | C19: =Follow[[#This Row],[CODRASTREIO]]&" B" -> CódRastreio594 B | D19: =_xlfn.XLOOKUP(Follow[[#This Row],[Id Pedido]],Controle_Pedidos[Número Pedido Cliente],Controle_Pedidos[Loja]) -> BV | E19: =_xlfn.XLOOKUP(Follow[[#This Row],[Id Pedido]],Controle_Pedidos[Número Pedido Cliente],Controle_Pedidos[Prazo Entrega]) -> 45686 | F19: Transp 1 | G19: - | H19: China | I19: Brasil | J19: 45686 | K19: Entregue | L19: ENTREGUE | M19: - | N19: =IF(Follow[[#This Row],[DATAATUALIZAÇÃO]]<=Follow[[#This Row],[Prev Entrega]],"Dentro do Prazo","Fora do Prazo") -> Dentro do Prazo | O19: =_xlfn.CONCAT("Olá ",PROPER(LOWER(TRIM(LEFT(SUBSTITUTE(_xlfn.XLOOKUP(Follow[[#This Row],[Id Pedido]],Controle_Pedidos[Número Pedido Cliente],Controle_Pedidos[NOME])," ",REPT(" ",100)),100)))),", Identificamos que o Item ",_xlfn.XLOOKUP(Follow[[#This Row],[Id Pedido]],Controle_Pedidos[Número Pedido Cliente],Controle_Pedidos[Nome Produto])," foi entregue no dia ",TEXT(Follow[[#This Row],[DATAATUALIZAÇÃO]],"dd/mm/aaaa"),", referente ao pedido Nº ",Follow[[#This Row],[Id Pedido]]," Rastreio ",IF(Follow[[#This Row],[Novo Cód de Rastreio]]="-",Follow[[#This Row],[Id Pedido]],Follow[[#This Row],[Novo Cód de Rastreio]]),", agradecemos a preferência e adoraríamos receber sua avaliação, tendo qualquer dúvida estamos à disposição.",_xlfn.IFS(Follow[[#This Row],[Loja]]="bv"," Att Tem tudo Shop",Follow[[#This Row],[Loja]]="mei"," Att NTA Variedades",Follow[[#This Row],[Loja]]="go"," Att Sec Variedades")) -> Olá Nome, Identificamos que o Item Ventilador Preto foi entregue no dia 29/01/2025, referente ao pedido Nº Pedido 611 Rastreio Pedido 611, agradecemos a preferência e adoraríamos receber sua avaliação, tendo qualquer dúvida estamos à disposição. Att Tem tudo Shop
A20: =_xlfn.XLOOKUP(Follow[[#This Row],[CODRASTREIO]],Controle_Pedidos[Cód Rastreamento],Controle_Pedidos[Número Pedido Cliente]) -> Pedido 632 | B20: CódRastreio614 | C20: =Follow[[#This Row],[CODRASTREIO]]&" B" -> CódRastreio614 B | D20: =_xlfn.XLOOKUP(Follow[[#This Row],[Id Pedido]],Controle_Pedidos[Número Pedido Cliente],Controle_Pedidos[Loja]) -> BV | E20: =_xlfn.XLOOKUP(Follow[[#This Row],[Id Pedido]],Controle_Pedidos[Número Pedido Cliente],Controle_Pedidos[Prazo Entrega]) -> 45688 | F20: Transp 1 | G20: - | H20: China | I20: Brasil | J20: 45674 | K20: Entregue | L20: ENTREGUE | M20: - | N20: =IF(Follow[[#This Row],[DATAATUALIZAÇÃO]]<=Follow[[#This Row],[Prev Entrega]],"Dentro do Prazo","Fora do Prazo") -> Dentro do Prazo | O20: =_xlfn.CONCAT("Olá ",PROPER(LOWER(TRIM(LEFT(SUBSTITUTE(_xlfn.XLOOKUP(Follow[[#This Row],[Id Pedido]],Controle_Pedidos[Número Pedido Cliente],Controle_Pedidos[NOME])," ",REPT(" ",100)),100)))),", Identificamos que o Item ",_xlfn.XLOOKUP(Follow[[#This Row],[Id Pedido]],Controle_Pedidos[Número Pedido Cliente],Controle_Pedidos[Nome Produto])," foi entregue no dia ",TEXT(Follow[[#This Row],[DATAATUALIZAÇÃO]],"dd/mm/aaaa"),", referente ao pedido Nº ",Follow[[#This Row],[Id Pedido]]," Rastreio ",IF(Follow[[#This Row],[Novo Cód de Rastreio]]="-",Follow[[#This Row],[Id Pedido]],Follow[[#This Row],[Novo Cód de Rastreio]]),", agradecemos a preferência e adoraríamos receber sua avaliação, tendo qualquer dúvida estamos à disposição.",_xlfn.IFS(Follow[[#This Row],[Loja]]="bv"," Att Tem tudo Shop",Follow[[#This Row],[Loja]]="mei"," Att NTA Variedades",Follow[[#This Row],[Loja]]="go"," Att Sec Variedades")) -> Olá Nome, Identificamos que o Item Ventilador Rosa foi entregue no dia 17/01/2025, referente ao pedido Nº Pedido 632 Rastreio Pedido 632, agradecemos a preferência e adoraríamos receber sua avaliação, tendo qualquer dúvida estamos à disposição. Att Tem tudo Shop
A21: =_xlfn.XLOOKUP(Follow[[#This Row],[CODRASTREIO]],Controle_Pedidos[Cód Rastreamento],Controle_Pedidos[Número Pedido Cliente]) -> Pedido 644 | B21: CódRastreio625 | C21: =Follow[[#This Row],[CODRASTREIO]]&" B" -> CódRastreio625 B | D21: =_xlfn.XLOOKUP(Follow[[#This Row],[Id Pedido]],Controle_Pedidos[Número Pedido Cliente],Controle_Pedidos[Loja]) -> BV | E21: =_xlfn.XLOOKUP(Follow[[#This Row],[Id Pedido]],Controle_Pedidos[Número Pedido Cliente],Controle_Pedidos[Prazo Entrega]) -> 45682 | F21: Transp 1 | G21: - | H21: Brasil | I21: Brasil | J21: 45673 | K21: Entregue | L21: ENTREGUE | M21: - | N21: =IF(Follow[[#This Row],[DATAATUALIZAÇÃO]]<=Follow[[#This Row],[Prev Entrega]],"Dentro do Prazo","Fora do Prazo") -> Dentro do Prazo | O21: =_xlfn.CONCAT("Olá ",PROPER(LOWER(TRIM(LEFT(SUBSTITUTE(_xlfn.XLOOKUP(Follow[[#This Row],[Id Pedido]],Controle_Pedidos[Número Pedido Cliente],Controle_Pedidos[NOME])," ",REPT(" ",100)),100)))),", Identificamos que o Item ",_xlfn.XLOOKUP(Follow[[#This Row],[Id Pedido]],Controle_Pedidos[Número Pedido Cliente],Controle_Pedidos[Nome Produto])," foi entregue no dia ",TEXT(Follow[[#This Row],[DATAATUALIZAÇÃO]],"dd/mm/aaaa"),", referente ao pedido Nº ",Follow[[#This Row],[Id Pedido]]," Rastreio ",IF(Follow[[#This Row],[Novo Cód de Rastreio]]="-",Follow[[#This Row],[Id Pedido]],Follow[[#This Row],[Novo Cód de Rastreio]]),", agradecemos a preferência e adoraríamos receber sua avaliação, tendo qualquer dúvida estamos à disposição.",_xlfn.IFS(Follow[[#This Row],[Loja]]="bv"," Att Tem tudo Shop",Follow[[#This Row],[Loja]]="mei"," Att NTA Variedades",Follow[[#This Row],[Loja]]="go"," Att Sec Variedades")) -> Olá Nome, Identificamos que o Item Adaptador Bluetooph foi entregue no dia 16/01/2025, referente ao pedido Nº Pedido 644 Rastreio Pedido 644, agradecemos a preferência e adoraríamos receber sua avaliação, tendo qualquer dúvida estamos à disposição. Att Tem tudo Shop
A22: =_xlfn.XLOOKUP(Follow[[#This Row],[CODRASTREIO]],Controle_Pedidos[Cód Rastreamento],Controle_Pedidos[Número Pedido Cliente]) -> Pedido 665 | B22: CódRastreio645 | C22: =Follow[[#This Row],[CODRASTREIO]]&" B" -> CódRastreio645 B | D22: =_xlfn.XLOOKUP(Follow[[#This Row],[Id Pedido]],Controle_Pedidos[Número Pedido Cliente],Controle_Pedidos[Loja]) -> BV | E22: =_xlfn.XLOOKUP(Follow[[#This Row],[Id Pedido]],Controle_Pedidos[Número Pedido Cliente],Controle_Pedidos[Prazo Entrega]) -> 45685 | F22: Transp 1 | G22: - | H22: China | I22: Brasil | J22: 45679 | K22: Entregue | L22: ENTREGUE | M22: - | N22: =IF(Follow[[#This Row],[DATAATUALIZAÇÃO]]<=Follow[[#This Row],[Prev Entrega]],"Dentro do Prazo","Fora do Prazo") -> Dentro do Prazo | O22: =_xlfn.CONCAT("Olá ",PROPER(LOWER(TRIM(LEFT(SUBSTITUTE(_xlfn.XLOOKUP(Follow[[#This Row],[Id Pedido]],Controle_Pedidos[Número Pedido Cliente],Controle_Pedidos[NOME])," ",REPT(" ",100)),100)))),", Identificamos que o Item ",_xlfn.XLOOKUP(Follow[[#This Row],[Id Pedido]],Controle_Pedidos[Número Pedido Cliente],Controle_Pedidos[Nome Produto])," foi entregue no dia ",TEXT(Follow[[#This Row],[DATAATUALIZAÇÃO]],"dd/mm/aaaa"),", referente ao pedido Nº ",Follow[[#This Row],[Id Pedido]]," Rastreio ",IF(Follow[[#This Row],[Novo Cód de Rastreio]]="-",Follow[[#This Row],[Id Pedido]],Follow[[#This Row],[Novo Cód de Rastreio]]),", agradecemos a preferência e adoraríamos receber sua avaliação, tendo qualquer dúvida estamos à disposição.",_xlfn.IFS(Follow[[#This Row],[Loja]]="bv"," Att Tem tudo Shop",Follow[[#This Row],[Loja]]="mei"," Att NTA Variedades",Follow[[#This Row],[Loja]]="go"," Att Sec Variedades")) -> Olá Nome, Identificamos que o Item Karaoke portátil foi entregue no dia 22/01/2025, referente ao pedido Nº Pedido 665 Rastreio Pedido 665, agradecemos a preferência e adoraríamos receber sua avaliação, tendo qualquer dúvida estamos à disposição. Att Tem tudo Shop
A23: =_xlfn.XLOOKUP(Follow[[#This Row],[CODRASTREIO]],Controle_Pedidos[Cód Rastreamento],Controle_Pedidos[Número Pedido Cliente]) -> Pedido 677 | B23: CódRastreio657 | C23: =Follow[[#This Row],[CODRASTREIO]]&" B" -> CódRastreio657 B | D23: =_xlfn.XLOOKUP(Follow[[#This Row],[Id Pedido]],Controle_Pedidos[Número Pedido Cliente],Controle_Pedidos[Loja]) -> BV | E23: =_xlfn.XLOOKUP(Follow[[#This Row],[Id Pedido]],Controle_Pedidos[Número Pedido Cliente],Controle_Pedidos[Prazo Entrega]) -> 45686 | F23: Transp 1 | G23: - | H23: Brasil | I23: Brasil | J23: 45673 | K23: Entregue | L23: ENTREGUE | M23: - | N23: =IF(Follow[[#This Row],[DATAATUALIZAÇÃO]]<=Follow[[#This Row],[Prev Entrega]],"Dentro do Prazo","Fora do Prazo") -> Dentro do Prazo | O23: =_xlfn.CONCAT("Olá ",PROPER(LOWER(TRIM(LEFT(SUBSTITUTE(_xlfn.XLOOKUP(Follow[[#This Row],[Id Pedido]],Controle_Pedidos[Número Pedido Cliente],Controle_Pedidos[NOME])," ",REPT(" ",100)),100)))),", Identificamos que o Item ",_xlfn.XLOOKUP(Follow[[#This Row],[Id Pedido]],Controle_Pedidos[Número Pedido Cliente],Controle_Pedidos[Nome Produto])," foi entregue no dia ",TEXT(Follow[[#This Row],[DATAATUALIZAÇÃO]],"dd/mm/aaaa"),", referente ao pedido Nº ",Follow[[#This Row],[Id Pedido]]," Rastreio ",IF(Follow[[#This Row],[Novo Cód de Rastreio]]="-",Follow[[#This Row],[Id Pedido]],Follow[[#This Row],[Novo Cód de Rastreio]]),", agradecemos a preferência e adoraríamos receber sua avaliação, tendo qualquer dúvida estamos à disposição.",_xlfn.IFS(Follow[[#This Row],[Loja]]="bv"," Att Tem tudo Shop",Follow[[#This Row],[Loja]]="mei"," Att NTA Variedades",Follow[[#This Row],[Loja]]="go"," Att Sec Variedades")) -> Olá Nome, Identificamos que o Item Adaptador Bluetooph foi entregue no dia 16/01/2025, referente ao pedido Nº Pedido 677 Rastreio Pedido 677, agradecemos a preferência e adoraríamos receber sua avaliação, tendo qualquer dúvida estamos à disposição. Att Tem tudo Shop
A24: =_xlfn.XLOOKUP(Follow[[#This Row],[CODRASTREIO]],Controle_Pedidos[Cód Rastreamento],Controle_Pedidos[Número Pedido Cliente]) -> Pedido 680 | B24: CódRastreio660 | C24: =Follow[[#This Row],[CODRASTREIO]]&" B" -> CódRastreio660 B | D24: =_xlfn.XLOOKUP(Follow[[#This Row],[Id Pedido]],Controle_Pedidos[Número Pedido Cliente],Controle_Pedidos[Loja]) -> BV | E24: =_xlfn.XLOOKUP(Follow[[#This Row],[Id Pedido]],Controle_Pedidos[Número Pedido Cliente],Controle_Pedidos[Prazo Entrega]) -> 45686 | F24: Transp 1 | G24: - | H24: China | I24: Brasil | J24: 45673 | K24: Entregue | L24: ENTREGUE | M24: - | N24: =IF(Follow[[#This Row],[DATAATUALIZAÇÃO]]<=Follow[[#This Row],[Prev Entrega]],"Dentro do Prazo","Fora do Prazo") -> Dentro do Prazo | O24: =_xlfn.CONCAT("Olá ",PROPER(LOWER(TRIM(LEFT(SUBSTITUTE(_xlfn.XLOOKUP(Follow[[#This Row],[Id Pedido]],Controle_Pedidos[Número Pedido Cliente],Controle_Pedidos[NOME])," ",REPT(" ",100)),100)))),", Identificamos que o Item ",_xlfn.XLOOKUP(Follow[[#This Row],[Id Pedido]],Controle_Pedidos[Número Pedido Cliente],Controle_Pedidos[Nome Produto])," foi entregue no dia ",TEXT(Follow[[#This Row],[DATAATUALIZAÇÃO]],"dd/mm/aaaa"),", referente ao pedido Nº ",Follow[[#This Row],[Id Pedido]]," Rastreio ",IF(Follow[[#This Row],[Novo Cód de Rastreio]]="-",Follow[[#This Row],[Id Pedido]],Follow[[#This Row],[Novo Cód de Rastreio]]),", agradecemos a preferência e adoraríamos receber sua avaliação, tendo qualquer dúvida estamos à disposição.",_xlfn.IFS(Follow[[#This Row],[Loja]]="bv"," Att Tem tudo Shop",Follow[[#This Row],[Loja]]="mei"," Att NTA Variedades",Follow[[#This Row],[Loja]]="go"," Att Sec Variedades")) -> Olá Nome, Identificamos que o Item Ventilador Rosa foi entregue no dia 16/01/2025, referente ao pedido Nº Pedido 680 Rastreio Pedido 680, agradecemos a preferência e adoraríamos receber sua avaliação, tendo qualquer dúvida estamos à disposição. Att Tem tudo Shop
A25: =_xlfn.XLOOKUP(Follow[[#This Row],[CODRASTREIO]],Controle_Pedidos[Cód Rastreamento],Controle_Pedidos[Número Pedido Cliente]) -> Pedido 681 | B25: CódRastreio661 | C25: =Follow[[#This Row],[CODRASTREIO]]&" B" -> CódRastreio661 B | D25: =_xlfn.XLOOKUP(Follow[[#This Row],[Id Pedido]],Controle_Pedidos[Número Pedido Cliente],Controle_Pedidos[Loja]) -> BV | E25: =_xlfn.XLOOKUP(Follow[[#This Row],[Id Pedido]],Controle_Pedidos[Número Pedido Cliente],Controle_Pedidos[Prazo Entrega]) -> 45693 | F25: Transp 1 | G25: - | H25: China | I25: Brasil | J25: 45682 | K25: Entregue | L25: ENTREGUE | M25: - | N25: =IF(Follow[[#This Row],[DATAATUALIZAÇÃO]]<=Follow[[#This Row],[Prev Entrega]],"Dentro do Prazo","Fora do Prazo") -> Dentro do Prazo | O25: =_xlfn.CONCAT("Olá ",PROPER(LOWER(TRIM(LEFT(SUBSTITUTE(_xlfn.XLOOKUP(Follow[[#This Row],[Id Pedido]],Controle_Pedidos[Número Pedido Cliente],Controle_Pedidos[NOME])," ",REPT(" ",100)),100)))),", Identificamos que o Item ",_xlfn.XLOOKUP(Follow[[#This Row],[Id Pedido]],Controle_Pedidos[Número Pedido Cliente],Controle_Pedidos[Nome Produto])," foi entregue no dia ",TEXT(Follow[[#This Row],[DATAATUALIZAÇÃO]],"dd/mm/aaaa"),", referente ao pedido Nº ",Follow[[#This Row],[Id Pedido]]," Rastreio ",IF(Follow[[#This Row],[Novo Cód de Rastreio]]="-",Follow[[#This Row],[Id Pedido]],Follow[[#This Row],[Novo Cód de Rastreio]]),", agradecemos a preferência e adoraríamos receber sua avaliação, tendo qualquer dúvida estamos à disposição.",_xlfn.IFS(Follow[[#This Row],[Loja]]="bv"," Att Tem tudo Shop",Follow[[#This Row],[Loja]]="mei"," Att NTA Variedades",Follow[[#This Row],[Loja]]="go"," Att Sec Variedades")) -> Olá Nome, Identificamos que o Item Ventilador Preto foi entregue no dia 25/01/2025, referente ao pedido Nº Pedido 681 Rastreio Pedido 681, agradecemos a preferência e adoraríamos receber sua avaliação, tendo qualquer dúvida estamos à disposição. Att Tem tudo Shop
A26: =_xlfn.XLOOKUP(Follow[[#This Row],[CODRASTREIO]],Controle_Pedidos[Cód Rastreamento],Controle_Pedidos[Número Pedido Cliente]) -> Pedido 684 | B26: CódRastreio664 | C26: =Follow[[#This Row],[CODRASTREIO]]&" B" -> CódRastreio664 B | D26: =_xlfn.XLOOKUP(Follow[[#This Row],[Id Pedido]],Controle_Pedidos[Número Pedido Cliente],Controle_Pedidos[Loja]) -> BV | E26: =_xlfn.XLOOKUP(Follow[[#This Row],[Id Pedido]],Controle_Pedidos[Número Pedido Cliente],Controle_Pedidos[Prazo Entrega]) -> 45693 | F26: Transp 1 | G26: - | H26: China | I26: Brasil | J26: 45687 | K26: Entregue | L26: ENTREGUE | M26: - | N26: =IF(Follow[[#This Row],[DATAATUALIZAÇÃO]]<=Follow[[#This Row],[Prev Entrega]],"Dentro do Prazo","Fora do Prazo") -> Dentro do Prazo | O26: =_xlfn.CONCAT("Olá ",PROPER(LOWER(TRIM(LEFT(SUBSTITUTE(_xlfn.XLOOKUP(Follow[[#This Row],[Id Pedido]],Controle_Pedidos[Número Pedido Cliente],Controle_Pedidos[NOME])," ",REPT(" ",100)),100)))),", Identificamos que o Item ",_xlfn.XLOOKUP(Follow[[#This Row],[Id Pedido]],Controle_Pedidos[Número Pedido Cliente],Controle_Pedidos[Nome Produto])," foi entregue no dia ",TEXT(Follow[[#This Row],[DATAATUALIZAÇÃO]],"dd/mm/aaaa"),", referente ao pedido Nº ",Follow[[#This Row],[Id Pedido]]," Rastreio ",IF(Follow[[#This Row],[Novo Cód de Rastreio]]="-",Follow[[#This Row],[Id Pedido]],Follow[[#This Row],[Novo Cód de Rastreio]]),", agradecemos a preferência e adoraríamos receber sua avaliação, tendo qualquer dúvida estamos à disposição.",_xlfn.IFS(Follow[[#This Row],[Loja]]="bv"," Att Tem tudo Shop",Follow[[#This Row],[Loja]]="mei"," Att NTA Variedades",Follow[[#This Row],[Loja]]="go"," Att Sec Variedades")) -> Olá Nome, Identificamos que o Item Ventilador Preto foi entregue no dia 30/01/2025, referente ao pedido Nº Pedido 684 Rastreio Pedido 684, agradecemos a preferência e adoraríamos receber sua avaliação, tendo qualquer dúvida estamos à disposição. Att Tem tudo Shop
A27: =_xlfn.XLOOKUP(Follow[[#This Row],[CODRASTREIO]],Controle_Pedidos[Cód Rastreamento],Controle_Pedidos[Número Pedido Cliente]) -> Pedido 682 | B27: CódRastreio662 | C27: =Follow[[#This Row],[CODRASTREIO]]&" B" -> CódRastreio662 B | D27: =_xlfn.XLOOKUP(Follow[[#This Row],[Id Pedido]],Controle_Pedidos[Número Pedido Cliente],Controle_Pedidos[Loja]) -> BV | E27: =_xlfn.XLOOKUP(Follow[[#This Row],[Id Pedido]],Controle_Pedidos[Número Pedido Cliente],Controle_Pedidos[Prazo Entrega]) -> 45686 | F27: Transp 1 | G27: - | H27: China | I27: Brasil | J27: 45674 | K27: Entregue | L27: ENTREGUE | M27: - | N27: =IF(Follow[[#This Row],[DATAATUALIZAÇÃO]]<=Follow[[#This Row],[Prev Entrega]],"Dentro do Prazo","Fora do Prazo") -> Dentro do Prazo | O27: =_xlfn.CONCAT("Olá ",PROPER(LOWER(TRIM(LEFT(SUBSTITUTE(_xlfn.XLOOKUP(Follow[[#This Row],[Id Pedido]],Controle_Pedidos[Número Pedido Cliente],Controle_Pedidos[NOME])," ",REPT(" ",100)),100)))),", Identificamos que o Item ",_xlfn.XLOOKUP(Follow[[#This Row],[Id Pedido]],Controle_Pedidos[Número Pedido Cliente],Controle_Pedidos[Nome Produto])," foi entregue no dia ",TEXT(Follow[[#This Row],[DATAATUALIZAÇÃO]],"dd/mm/aaaa"),", referente ao pedido Nº ",Follow[[#This Row],[Id Pedido]]," Rastreio ",IF(Follow[[#This Row],[Novo Cód de Rastreio]]="-",Follow[[#This Row],[Id Pedido]],Follow[[#This Row],[Novo Cód de Rastreio]]),", agradecemos a preferência e adoraríamos receber sua avaliação, tendo qualquer dúvida estamos à disposição.",_xlfn.IFS(Follow[[#This Row],[Loja]]="bv"," Att Tem tudo Shop",Follow[[#This Row],[Loja]]="mei"," Att NTA Variedades",Follow[[#This Row],[Loja]]="go"," Att Sec Variedades")) -> Olá Nome, Identificamos que o Item Karaoke portátil foi entregue no dia 17/01/2025, referente ao pedido Nº Pedido 682 Rastreio Pedido 682, agradecemos a preferência e adoraríamos receber sua avaliação, tendo qualquer dúvida estamos à disposição. Att Tem tudo Shop
A28: =_xlfn.XLOOKUP(Follow[[#This Row],[CODRASTREIO]],Controle_Pedidos[Cód Rastreamento],Controle_Pedidos[Número Pedido Cliente]) -> Pedido 686 | B28: CódRastreio666 | C28: =Follow[[#This Row],[CODRASTREIO]]&" B" -> CódRastreio666 B | D28: =_xlfn.XLOOKUP(Follow[[#This Row],[Id Pedido]],Controle_Pedidos[Número Pedido Cliente],Controle_Pedidos[Loja]) -> BV | E28: =_xlfn.XLOOKUP(Follow[[#This Row],[Id Pedido]],Controle_Pedidos[Número Pedido Cliente],Controle_Pedidos[Prazo Entrega]) -> 45686 | F28: Transp 1 | G28: - | H28: China | I28: Brasil | J28: 45677 | K28: Entregue | L28: ENTREGUE | M28: - | N28: =IF(Follow[[#This Row],[DATAATUALIZAÇÃO]]<=Follow[[#This Row],[Prev Entrega]],"Dentro do Prazo","Fora do Prazo") -> Dentro do Prazo | O28: =_xlfn.CONCAT("Olá ",PROPER(LOWER(TRIM(LEFT(SUBSTITUTE(_xlfn.XLOOKUP(Follow[[#This Row],[Id Pedido]],Controle_Pedidos[Número Pedido Cliente],Controle_Pedidos[NOME])," ",REPT(" ",100)),100)))),", Identificamos que o Item ",_xlfn.XLOOKUP(Follow[[#This Row],[Id Pedido]],Controle_Pedidos[Número Pedido Cliente],Controle_Pedidos[Nome Produto])," foi entregue no dia ",TEXT(Follow[[#This Row],[DATAATUALIZAÇÃO]],"dd/mm/aaaa"),", referente ao pedido Nº ",Follow[[#This Row],[Id Pedido]]," Rastreio ",IF(Follow[[#This Row],[Novo Cód de Rastreio]]="-",Follow[[#This Row],[Id Pedido]],Follow[[#This Row],[Novo Cód de Rastreio]]),", agradecemos a preferência e adoraríamos receber sua avaliação, tendo qualquer dúvida estamos à disposição.",_xlfn.IFS(Follow[[#This Row],[Loja]]="bv"," Att Tem tudo Shop",Follow[[#This Row],[Loja]]="mei"," Att NTA Variedades",Follow[[#This Row],[Loja]]="go"," Att Sec Variedades")) -> Olá Nome, Identificamos que o Item Ventilador Rosa foi entregue no dia 20/01/2025, referente ao pedido Nº Pedido 686 Rastreio Pedido 686, agradecemos a preferência e adoraríamos receber sua avaliação, tendo qualquer dúvida estamos à disposição. Att Tem tudo Shop
A29: =_xlfn.XLOOKUP(Follow[[#This Row],[CODRASTREIO]],Controle_Pedidos[Cód Rastreamento],Controle_Pedidos[Número Pedido Cliente]) -> Pedido 687 | B29: CódRastreio667 | C29: =Follow[[#This Row],[CODRASTREIO]]&" B" -> CódRastreio667 B | D29: =_xlfn.XLOOKUP(Follow[[#This Row],[Id Pedido]],Controle_Pedidos[Número Pedido Cliente],Controle_Pedidos[Loja]) -> BV | E29: =_xlfn.XLOOKUP(Follow[[#This Row],[Id Pedido]],Controle_Pedidos[Número Pedido Cliente],Controle_Pedidos[Prazo Entrega]) -> 45687 | F29: Transp 1 | G29: - | H29: China | I29: Brasil | J29: 45677 | K29: Entregue | L29: ENTREGUE | M29: - | N29: =IF(Follow[[#This Row],[DATAATUALIZAÇÃO]]<=Follow[[#This Row],[Prev Entrega]],"Dentro do Prazo","Fora do Prazo") -> Dentro do Prazo | O29: =_xlfn.CONCAT("Olá ",PROPER(LOWER(TRIM(LEFT(SUBSTITUTE(_xlfn.XLOOKUP(Follow[[#This Row],[Id Pedido]],Controle_Pedidos[Número Pedido Cliente],Controle_Pedidos[NOME])," ",REPT(" ",100)),100)))),", Identificamos que o Item ",_xlfn.XLOOKUP(Follow[[#This Row],[Id Pedido]],Controle_Pedidos[Número Pedido Cliente],Controle_Pedidos[Nome Produto])," foi entregue no dia ",TEXT(Follow[[#This Row],[DATAATUALIZAÇÃO]],"dd/mm/aaaa"),", referente ao pedido Nº ",Follow[[#This Row],[Id Pedido]]," Rastreio ",IF(Follow[[#This Row],[Novo Cód de Rastreio]]="-",Follow[[#This Row],[Id Pedido]],Follow[[#This Row],[Novo Cód de Rastreio]]),", agradecemos a preferência e adoraríamos receber sua avaliação, tendo qualquer dúvida estamos à disposição.",_xlfn.IFS(Follow[[#This Row],[Loja]]="bv"," Att Tem tudo Shop",Follow[[#This Row],[Loja]]="mei"," Att NTA Variedades",Follow[[#This Row],[Loja]]="go"," Att Sec Variedades")) -> Olá Nome, Identificamos que o Item Ventilador Preto foi entregue no dia 20/01/2025, referente ao pedido Nº Pedido 687 Rastreio Pedido 687, agradecemos a preferência e adoraríamos receber sua avaliação, tendo qualquer dúvida estamos à disposição. Att Tem tudo Shop
A30: =_xlfn.XLOOKUP(Follow[[#This Row],[CODRASTREIO]],Controle_Pedidos[Cód Rastreamento],Controle_Pedidos[Número Pedido Cliente]) -> Pedido 691 | B30: CódRastreio671 | C30: =Follow[[#This Row],[CODRASTREIO]]&" B" -> CódRastreio671 B | D30: =_xlfn.XLOOKUP(Follow[[#This Row],[Id Pedido]],Controle_Pedidos[Número Pedido Cliente],Controle_Pedidos[Loja]) -> BV | E30: =_xlfn.XLOOKUP(Follow[[#This Row],[Id Pedido]],Controle_Pedidos[Número Pedido Cliente],Controle_Pedidos[Prazo Entrega]) -> 45687 | F30: Transp 1 | G30: - | H30: China | I30: Brasil | J30: 45678 | K30: Entregue | L30: ENTREGUE | M30: Cliente Notificado | N30: =IF(Follow[[#This Row],[DATAATUALIZAÇÃO]]<=Follow[[#This Row],[Prev Entrega]],"Dentro do Prazo","Fora do Prazo") -> Dentro do Prazo | O30: =_xlfn.CONCAT("Olá ",PROPER(LOWER(TRIM(LEFT(SUBSTITUTE(_xlfn.XLOOKUP(Follow[[#This Row],[Id Pedido]],Controle_Pedidos[Número Pedido Cliente],Controle_Pedidos[NOME])," ",REPT(" ",100)),100)))),", Identificamos que o Item ",_xlfn.XLOOKUP(Follow[[#This Row],[Id Pedido]],Controle_Pedidos[Número Pedido Cliente],Controle_Pedidos[Nome Produto])," foi entregue no dia ",TEXT(Follow[[#This Row],[DATAATUALIZAÇÃO]],"dd/mm/aaaa"),", referente ao pedido Nº ",Follow[[#This Row],[Id Pedido]]," Rastreio ",IF(Follow[[#This Row],[Novo Cód de Rastreio]]="-",Follow[[#This Row],[Id Pedido]],Follow[[#This Row],[Novo Cód de Rastreio]]),", agradecemos a preferência e adoraríamos receber sua avaliação, tendo qualquer dúvida estamos à disposição.",_xlfn.IFS(Follow[[#This Row],[Loja]]="bv"," Att Tem tudo Shop",Follow[[#This Row],[Loja]]="mei"," Att NTA Variedades",Follow[[#This Row],[Loja]]="go"," Att Sec Variedades")) -> Olá Nome, Identificamos que o Item Ventilador Rosa foi entregue no dia 21/01/2025, referente ao pedido Nº Pedido 691 Rastreio Pedido 691, agradecemos a preferência e adoraríamos receber sua avaliação, tendo qualquer dúvida estamos à disposição. Att Tem tudo Shop
... A252: =_xlfn.XLOOKUP(Follow[[#This Row],[CODRASTREIO]],Controle_Pedidos[Cód Rastreamento],Controle_Pedidos[Número Pedido Cliente]) -> Pedido 70 | B252: CódRastreio61 | C252: =Follow[[#This Row],[CODRASTREIO]]&" B" -> CódRastreio61 B | D252: =_xlfn.XLOOKUP(Follow[[#This Row],[Id Pedido]],Controle_Pedidos[Número Pedido Cliente],Controle_Pedidos[Loja]) -> BV | E252: =_xlfn.XLOOKUP(Follow[[#This Row],[Id Pedido]],Controle_Pedidos[Número Pedido Cliente],Controle_Pedidos[Prazo Entrega]) -> 45603 | F252: Transp 1 | G252: - | H252: Brasil | I252: Brasil | J252: 45594 | K252: Entregue | L252: ENTREGUE | M252: - | N252: =IF(Follow[[#This Row],[DATAATUALIZAÇÃO]]<=Follow[[#This Row],[Prev Entrega]],"Dentro do Prazo","Fora do Prazo") -> Dentro do Prazo | O252: =_xlfn.CONCAT("Olá ",PROPER(LOWER(TRIM(LEFT(SUBSTITUTE(_xlfn.XLOOKUP(Follow[[#This Row],[Id Pedido]],Controle_Pedidos[Número Pedido Cliente],Controle_Pedidos[NOME])," ",REPT(" ",100)),100)))),", Identificamos que o Item ",_xlfn.XLOOKUP(Follow[[#This Row],[Id Pedido]],Controle_Pedidos[Número Pedido Cliente],Controle_Pedidos[Nome Produto])," foi entregue no dia ",TEXT(Follow[[#This Row],[DATAATUALIZAÇÃO]],"dd/mm/aaaa"),", referente ao pedido Nº ",Follow[[#This Row],[Id Pedido]]," Rastreio ",IF(Follow[[#This Row],[Novo Cód de Rastreio]]="-",Follow[[#This Row],[Id Pedido]],Follow[[#This Row],[Novo Cód de Rastreio]]),", agradecemos a preferência e adoraríamos receber sua avaliação, tendo qualquer dúvida estamos à disposição.",_xlfn.IFS(Follow[[#This Row],[Loja]]="bv"," Att Tem tudo Shop",Follow[[#This Row],[Loja]]="mei"," Att NTA Variedades",Follow[[#This Row],[Loja]]="go"," Att Sec Variedades")) -> Olá Nome, Identificamos que o Item Suporte de Celular Branco foi entregue no dia 29/10/2024, referente ao pedido Nº Pedido 70 Rastreio Pedido 70, agradecemos a preferência e adoraríamos receber sua avaliação, tendo qualquer dúvida estamos à disposição. Att Tem tudo Shop
A253: Pedido 426 | B253: CódRastreio413 1 envio | C253: =Follow[[#This Row],[CODRASTREIO]]&" B" -> CódRastreio413 1 envio B | D253: BV | E253: 45645 | F253: Transp 1 | G253: - | H253: Brasil | I253: Brasil | J253: 45629 | K253: Entregue | L253: ENTREGUE | M253: - | N253: =IF(Follow[[#This Row],[DATAATUALIZAÇÃO]]<=Follow[[#This Row],[Prev Entrega]],"Dentro do Prazo","Fora do Prazo") -> Dentro do Prazo | O253: =_xlfn.CONCAT("Olá ",PROPER(LOWER(TRIM(LEFT(SUBSTITUTE(_xlfn.XLOOKUP(Follow[[#This Row],[Id Pedido]],Controle_Pedidos[Número Pedido Cliente],Controle_Pedidos[NOME])," ",REPT(" ",100)),100)))),", Identificamos que o Item ",_xlfn.XLOOKUP(Follow[[#This Row],[Id Pedido]],Controle_Pedidos[Número Pedido Cliente],Controle_Pedidos[Nome Produto])," foi entregue no dia ",TEXT(Follow[[#This Row],[DATAATUALIZAÇÃO]],"dd/mm/aaaa"),", referente ao pedido Nº ",Follow[[#This Row],[Id Pedido]]," Rastreio ",IF(Follow[[#This Row],[Novo Cód de Rastreio]]="-",Follow[[#This Row],[Id Pedido]],Follow[[#This Row],[Novo Cód de Rastreio]]),", agradecemos a preferência e adoraríamos receber sua avaliação, tendo qualquer dúvida estamos à disposição.",_xlfn.IFS(Follow[[#This Row],[Loja]]="bv"," Att Tem tudo Shop",Follow[[#This Row],[Loja]]="mei"," Att NTA Variedades",Follow[[#This Row],[Loja]]="go"," Att Sec Variedades")) -> Olá Nome, Identificamos que o Item Adaptador Bluetooph foi entregue no dia 03/12/2024, referente ao pedido Nº Pedido 426 Rastreio Pedido 426, agradecemos a preferência e adoraríamos receber sua avaliação, tendo qualquer dúvida estamos à disposição. Att Tem tudo Shop
A254: Pedido 426 | B254: CódRastreio413 2 Envio | C254: =Follow[[#This Row],[CODRASTREIO]]&" B" -> CódRastreio413 2 Envio B | D254: BV | E254: 45645 | F254: Transp 1 | G254: - | H254: Brasil | I254: Brasil | J254: 45629 | K254: Entregue | L254: ENTREGUE | M254: - | N254: =IF(Follow[[#This Row],[DATAATUALIZAÇÃO]]<=Follow[[#This Row],[Prev Entrega]],"Dentro do Prazo","Fora do Prazo") -> Dentro do Prazo | O254: =_xlfn.CONCAT("Olá ",PROPER(LOWER(TRIM(LEFT(SUBSTITUTE(_xlfn.XLOOKUP(Follow[[#This Row],[Id Pedido]],Controle_Pedidos[Número Pedido Cliente],Controle_Pedidos[NOME])," ",REPT(" ",100)),100)))),", Identificamos que o Item ",_xlfn.XLOOKUP(Follow[[#This Row],[Id Pedido]],Controle_Pedidos[Número Pedido Cliente],Controle_Pedidos[Nome Produto])," foi entregue no dia ",TEXT(Follow[[#This Row],[DATAATUALIZAÇÃO]],"dd/mm/aaaa"),", referente ao pedido Nº ",Follow[[#This Row],[Id Pedido]]," Rastreio ",IF(Follow[[#This Row],[Novo Cód de Rastreio]]="-",Follow[[#This Row],[Id Pedido]],Follow[[#This Row],[Novo Cód de Rastreio]]),", agradecemos a preferência e adoraríamos receber sua avaliação, tendo qualquer dúvida estamos à disposição.",_xlfn.IFS(Follow[[#This Row],[Loja]]="bv"," Att Tem tudo Shop",Follow[[#This Row],[Loja]]="mei"," Att NTA Variedades",Follow[[#This Row],[Loja]]="go"," Att Sec Variedades")) -> Olá Nome, Identificamos que o Item Adaptador Bluetooph foi entregue no dia 03/12/2024, referente ao pedido Nº Pedido 426 Rastreio Pedido 426, agradecemos a preferência e adoraríamos receber sua avaliação, tendo qualquer dúvida estamos à disposição. Att Tem tudo Shop
A255: =_xlfn.XLOOKUP(Follow[[#This Row],[CODRASTREIO]],Controle_Pedidos[Cód Rastreamento],Controle_Pedidos[Número Pedido Cliente]) -> Pedido 426 | B255: CódRastreio413 | C255: =Follow[[#This Row],[CODRASTREIO]]&" B" -> CódRastreio413 B | D255: =_xlfn.XLOOKUP(Follow[[#This Row],[Id Pedido]],Controle_Pedidos[Número Pedido Cliente],Controle_Pedidos[Loja]) -> BV | E255: =_xlfn.XLOOKUP(Follow[[#This Row],[Id Pedido]],Controle_Pedidos[Número Pedido Cliente],Controle_Pedidos[Prazo Entrega]) -> 45645 | F255: Transp 1 | G255: - | H255: Brasil | I255: Brasil | J255: 45630 | K255: Entregue | L255: ENTREGUE | M255: - | N255: =IF(Follow[[#This Row],[DATAATUALIZAÇÃO]]<=Follow[[#This Row],[Prev Entrega]],"Dentro do Prazo","Fora do Prazo") -> Dentro do Prazo | O255: =_xlfn.CONCAT("Olá ",PROPER(LOWER(TRIM(LEFT(SUBSTITUTE(_xlfn.XLOOKUP(Follow[[#This Row],[Id Pedido]],Controle_Pedidos[Número Pedido Cliente],Controle_Pedidos[NOME])," ",REPT(" ",100)),100)))),", Identificamos que o Item ",_xlfn.XLOOKUP(Follow[[#This Row],[Id Pedido]],Controle_Pedidos[Número Pedido Cliente],Controle_Pedidos[Nome Produto])," foi entregue no dia ",TEXT(Follow[[#This Row],[DATAATUALIZAÇÃO]],"dd/mm/aaaa"),", referente ao pedido Nº ",Follow[[#This Row],[Id Pedido]]," Rastreio ",IF(Follow[[#This Row],[Novo Cód de Rastreio]]="-",Follow[[#This Row],[Id Pedido]],Follow[[#This Row],[Novo Cód de Rastreio]]),", agradecemos a preferência e adoraríamos receber sua avaliação, tendo qualquer dúvida estamos à disposição.",_xlfn.IFS(Follow[[#This Row],[Loja]]="bv"," Att Tem tudo Shop",Follow[[#This Row],[Loja]]="mei"," Att NTA Variedades",Follow[[#This Row],[Loja]]="go"," Att Sec Variedades")) -> Olá Nome, Identificamos que o Item Adaptador Bluetooph foi entregue no dia 04/12/2024, referente ao pedido Nº Pedido 426 Rastreio Pedido 426, agradecemos a preferência e adoraríamos receber sua avaliação, tendo qualquer dúvida estamos à disposição. Att Tem tudo Shop
